[2024-09-25T01:37:47.293+0000] {local_task_job_runner.py:123} INFO - ::group::Pre task execution logs
[2024-09-25T01:37:47.310+0000] {taskinstance.py:2612} INFO - Dependencies all met for dep_context=non-requeueable deps ti=<TaskInstance: fetch_and_store_amazon_books.insert_book_data scheduled__2024-07-02T00:00:00+00:00 [queued]>
[2024-09-25T01:37:47.318+0000] {taskinstance.py:2612} INFO - Dependencies all met for dep_context=requeueable deps ti=<TaskInstance: fetch_and_store_amazon_books.insert_book_data scheduled__2024-07-02T00:00:00+00:00 [queued]>
[2024-09-25T01:37:47.320+0000] {taskinstance.py:2865} INFO - Starting attempt 2 of 2
[2024-09-25T01:37:47.335+0000] {taskinstance.py:2888} INFO - Executing <Task(PythonOperator): insert_book_data> on 2024-07-02 00:00:00+00:00
[2024-09-25T01:37:47.341+0000] {warnings.py:112} WARNING - /home/***/.local/lib/python3.12/site-packages/***/task/task_runner/standard_task_runner.py:70: DeprecationWarning: This process (pid=3246) is multi-threaded, use of fork() may lead to deadlocks in the child.
  pid = os.fork()

[2024-09-25T01:37:47.343+0000] {standard_task_runner.py:72} INFO - Started process 3254 to run task
[2024-09-25T01:37:47.343+0000] {standard_task_runner.py:104} INFO - Running: ['***', 'tasks', 'run', 'fetch_and_store_amazon_books', 'insert_book_data', 'scheduled__2024-07-02T00:00:00+00:00', '--job-id', '73', '--raw', '--subdir', 'DAGS_FOLDER/dag.py', '--cfg-path', '/tmp/tmp2z0_wqf_']
[2024-09-25T01:37:47.345+0000] {standard_task_runner.py:105} INFO - Job 73: Subtask insert_book_data
[2024-09-25T01:37:47.395+0000] {task_command.py:467} INFO - Running <TaskInstance: fetch_and_store_amazon_books.insert_book_data scheduled__2024-07-02T00:00:00+00:00 [running]> on host 12236234e313
[2024-09-25T01:37:47.472+0000] {taskinstance.py:3131} INFO - Exporting env vars: AIRFLOW_CTX_DAG_OWNER='***' AIRFLOW_CTX_DAG_ID='fetch_and_store_amazon_books' AIRFLOW_CTX_TASK_ID='insert_book_data' AIRFLOW_CTX_EXECUTION_DATE='2024-07-02T00:00:00+00:00' AIRFLOW_CTX_TRY_NUMBER='2' AIRFLOW_CTX_DAG_RUN_ID='scheduled__2024-07-02T00:00:00+00:00'
[2024-09-25T01:37:47.474+0000] {logging_mixin.py:190} INFO - Task instance is in running state
[2024-09-25T01:37:47.475+0000] {logging_mixin.py:190} INFO -  Previous state of the Task instance: queued
[2024-09-25T01:37:47.475+0000] {logging_mixin.py:190} INFO - Current task name:insert_book_data state:running start_date:2024-09-25 01:37:47.311247+00:00
[2024-09-25T01:37:47.476+0000] {logging_mixin.py:190} INFO - Dag name:fetch_and_store_amazon_books and current dag run status:running
[2024-09-25T01:37:47.477+0000] {taskinstance.py:731} INFO - ::endgroup::
[2024-09-25T01:37:47.495+0000] {base.py:84} INFO - Retrieving connection 'books_connection'
[2024-09-25T01:37:47.498+0000] {sql.py:509} INFO - Running statement: 
    INSERT INTO books (title, author, price, rating)
    VALUES (%s,%s,%s,%s)
    , parameters: ('Data Engineering with AWS - Second Edition: Acquire the skills to design and build AWS-based data transformation pipelines like a pro', 'Gareth Eagar', '41.', '4.4 out of 5 stars')
[2024-09-25T01:37:47.501+0000] {taskinstance.py:3310} ERROR - Task failed with exception
Traceback (most recent call last):
  File "/home/airflow/.local/lib/python3.12/site-packages/airflow/models/taskinstance.py", line 767, in _execute_task
    result = _execute_callable(context=context, **execute_callable_kwargs)
             ^^^^^^^^^^^^^^^^^^^^^^^^^^^^^^^^^^^^^^^^^^^^^^^^^^^^^^^^^^^^^
  File "/home/airflow/.local/lib/python3.12/site-packages/airflow/models/taskinstance.py", line 733, in _execute_callable
    return ExecutionCallableRunner(
           ^^^^^^^^^^^^^^^^^^^^^^^^
  File "/home/airflow/.local/lib/python3.12/site-packages/airflow/utils/operator_helpers.py", line 252, in run
    return self.func(*args, **kwargs)
           ^^^^^^^^^^^^^^^^^^^^^^^^^^
  File "/home/airflow/.local/lib/python3.12/site-packages/airflow/models/baseoperator.py", line 406, in wrapper
    return func(self, *args, **kwargs)
           ^^^^^^^^^^^^^^^^^^^^^^^^^^^
  File "/home/airflow/.local/lib/python3.12/site-packages/airflow/operators/python.py", line 238, in execute
    return_value = self.execute_callable()
                   ^^^^^^^^^^^^^^^^^^^^^^^
  File "/home/airflow/.local/lib/python3.12/site-packages/airflow/operators/python.py", line 256, in execute_callable
    return runner.run(*self.op_args, **self.op_kwargs)
           ^^^^^^^^^^^^^^^^^^^^^^^^^^^^^^^^^^^^^^^^^^^
  File "/home/airflow/.local/lib/python3.12/site-packages/airflow/utils/operator_helpers.py", line 252, in run
    return self.func(*args, **kwargs)
           ^^^^^^^^^^^^^^^^^^^^^^^^^^
  File "/opt/airflow/dags/dag.py", line 116, in insert_book_data_into_postgres
    postgres_hook.run(insert_query, parameters=(book['Title'], book['Author'],book['Price'],book['Rating'] ))
  File "/home/airflow/.local/lib/python3.12/site-packages/airflow/providers/common/sql/hooks/sql.py", line 456, in run
    self._run_command(cur, sql_statement, parameters)
  File "/home/airflow/.local/lib/python3.12/site-packages/airflow/providers/common/sql/hooks/sql.py", line 512, in _run_command
    cur.execute(sql_statement, parameters)
psycopg2.errors.UndefinedColumn: column "author" of relation "books" does not exist
LINE 2:     INSERT INTO books (title, author, price, rating)
                                      ^

[2024-09-25T01:37:47.516+0000] {logging_mixin.py:190} INFO - Task instance in failure state
[2024-09-25T01:37:47.517+0000] {logging_mixin.py:190} INFO - Task start:2024-09-25 01:37:47.311247+00:00 end:2024-09-25 01:37:47.515804+00:00 duration:0.204557
[2024-09-25T01:37:47.518+0000] {logging_mixin.py:190} INFO - Task:<Task(PythonOperator): insert_book_data> dag:<DAG: fetch_and_store_amazon_books> dagrun:<DagRun fetch_and_store_amazon_books @ 2024-07-02 00:00:00+00:00: scheduled__2024-07-02T00:00:00+00:00, state:running, queued_at: 2024-09-25 01:25:21.848943+00:00. externally triggered: False>
[2024-09-25T01:37:47.518+0000] {logging_mixin.py:190} INFO - Failure caused by column "author" of relation "books" does not exist
LINE 2:     INSERT INTO books (title, author, price, rating)
                                      ^
[2024-09-25T01:37:47.519+0000] {taskinstance.py:1225} INFO - Marking task as FAILED. dag_id=fetch_and_store_amazon_books, task_id=insert_book_data, run_id=scheduled__2024-07-02T00:00:00+00:00, execution_date=20240702T000000, start_date=20240925T013747, end_date=20240925T013747
[2024-09-25T01:37:47.529+0000] {taskinstance.py:340} INFO - ::group::Post task execution logs
[2024-09-25T01:37:47.530+0000] {standard_task_runner.py:124} ERROR - Failed to execute job 73 for task insert_book_data (column "author" of relation "books" does not exist
LINE 2:     INSERT INTO books (title, author, price, rating)
                                      ^
; 3254)
Traceback (most recent call last):
  File "/home/airflow/.local/lib/python3.12/site-packages/airflow/task/task_runner/standard_task_runner.py", line 117, in _start_by_fork
    ret = args.func(args, dag=self.dag)
          ^^^^^^^^^^^^^^^^^^^^^^^^^^^^^
  File "/home/airflow/.local/lib/python3.12/site-packages/airflow/cli/cli_config.py", line 49, in command
    return func(*args, **kwargs)
           ^^^^^^^^^^^^^^^^^^^^^
  File "/home/airflow/.local/lib/python3.12/site-packages/airflow/utils/cli.py", line 115, in wrapper
    return f(*args, **kwargs)
           ^^^^^^^^^^^^^^^^^^
  File "/home/airflow/.local/lib/python3.12/site-packages/airflow/cli/commands/task_command.py", line 483, in task_run
    task_return_code = _run_task_by_selected_method(args, _dag, ti)
                       ^^^^^^^^^^^^^^^^^^^^^^^^^^^^^^^^^^^^^^^^^^^^
  File "/home/airflow/.local/lib/python3.12/site-packages/airflow/cli/commands/task_command.py", line 256, in _run_task_by_selected_method
    return _run_raw_task(args, ti)
           ^^^^^^^^^^^^^^^^^^^^^^^
  File "/home/airflow/.local/lib/python3.12/site-packages/airflow/cli/commands/task_command.py", line 341, in _run_raw_task
    return ti._run_raw_task(
           ^^^^^^^^^^^^^^^^^
  File "/home/airflow/.local/lib/python3.12/site-packages/airflow/utils/session.py", line 97, in wrapper
    return func(*args, session=session, **kwargs)
           ^^^^^^^^^^^^^^^^^^^^^^^^^^^^^^^^^^^^^^
  File "/home/airflow/.local/lib/python3.12/site-packages/airflow/models/taskinstance.py", line 3004, in _run_raw_task
    return _run_raw_task(
           ^^^^^^^^^^^^^^
  File "/home/airflow/.local/lib/python3.12/site-packages/airflow/models/taskinstance.py", line 273, in _run_raw_task
    TaskInstance._execute_task_with_callbacks(
  File "/home/airflow/.local/lib/python3.12/site-packages/airflow/models/taskinstance.py", line 3158, in _execute_task_with_callbacks
    result = self._execute_task(context, task_orig)
             ^^^^^^^^^^^^^^^^^^^^^^^^^^^^^^^^^^^^^^
  File "/home/airflow/.local/lib/python3.12/site-packages/airflow/models/taskinstance.py", line 3182, in _execute_task
    return _execute_task(self, context, task_orig)
           ^^^^^^^^^^^^^^^^^^^^^^^^^^^^^^^^^^^^^^^
  File "/home/airflow/.local/lib/python3.12/site-packages/airflow/models/taskinstance.py", line 767, in _execute_task
    result = _execute_callable(context=context, **execute_callable_kwargs)
             ^^^^^^^^^^^^^^^^^^^^^^^^^^^^^^^^^^^^^^^^^^^^^^^^^^^^^^^^^^^^^
  File "/home/airflow/.local/lib/python3.12/site-packages/airflow/models/taskinstance.py", line 733, in _execute_callable
    return ExecutionCallableRunner(
           ^^^^^^^^^^^^^^^^^^^^^^^^
  File "/home/airflow/.local/lib/python3.12/site-packages/airflow/utils/operator_helpers.py", line 252, in run
    return self.func(*args, **kwargs)
           ^^^^^^^^^^^^^^^^^^^^^^^^^^
  File "/home/airflow/.local/lib/python3.12/site-packages/airflow/models/baseoperator.py", line 406, in wrapper
    return func(self, *args, **kwargs)
           ^^^^^^^^^^^^^^^^^^^^^^^^^^^
  File "/home/airflow/.local/lib/python3.12/site-packages/airflow/operators/python.py", line 238, in execute
    return_value = self.execute_callable()
                   ^^^^^^^^^^^^^^^^^^^^^^^
  File "/home/airflow/.local/lib/python3.12/site-packages/airflow/operators/python.py", line 256, in execute_callable
    return runner.run(*self.op_args, **self.op_kwargs)
           ^^^^^^^^^^^^^^^^^^^^^^^^^^^^^^^^^^^^^^^^^^^
  File "/home/airflow/.local/lib/python3.12/site-packages/airflow/utils/operator_helpers.py", line 252, in run
    return self.func(*args, **kwargs)
           ^^^^^^^^^^^^^^^^^^^^^^^^^^
  File "/opt/airflow/dags/dag.py", line 116, in insert_book_data_into_postgres
    postgres_hook.run(insert_query, parameters=(book['Title'], book['Author'],book['Price'],book['Rating'] ))
  File "/home/airflow/.local/lib/python3.12/site-packages/airflow/providers/common/sql/hooks/sql.py", line 456, in run
    self._run_command(cur, sql_statement, parameters)
  File "/home/airflow/.local/lib/python3.12/site-packages/airflow/providers/common/sql/hooks/sql.py", line 512, in _run_command
    cur.execute(sql_statement, parameters)
psycopg2.errors.UndefinedColumn: column "author" of relation "books" does not exist
LINE 2:     INSERT INTO books (title, author, price, rating)
                                      ^

[2024-09-25T01:37:47.560+0000] {local_task_job_runner.py:266} INFO - Task exited with return code 1
[2024-09-25T01:37:47.575+0000] {taskinstance.py:3900} INFO - 0 downstream tasks scheduled from follow-on schedule check
[2024-09-25T01:37:47.577+0000] {local_task_job_runner.py:245} INFO - ::endgroup::
